Workbook

Sheet Bank_Statement
A1: Date | B1: Transaction_ID | C1: Description | D1: Debit | E1: Credit | F1: Balance | H1: Match Status
A2: 01-04-2026 | B2: TXN1000 | C2: UTILITY BILL | D2: 3953 | F2: 46047 | H2: =IF(ISNA(VLOOKUP(B2,Cash_Book!B:B,1,FALSE)),"Missing","Found") -> Missing
A3: 02-04-2026 | B3: TXN1001 | C3: CLIENT PAYMENT | E3: 9769 | F3: 55816 | H3: =IF(ISNA(VLOOKUP(B3,Cash_Book!B:D,2,FALSE)),"Missing","Found") -> Found
A4: 03-04-2026 | B4: TXN1002 | C4: EFT PAYMENT | D4: 4142 | F4: 51674 | H4: =IF(ISNA(VLOOKUP(B4,Cash_Book!B:D,2,FALSE)),"Missing","Found") -> Found
A5: 04-04-2026 | B5: TXN1003 | C5: EFT RECEIPT | E5: 4282 | F5: 55956 | H5: =IF(ISNA(VLOOKUP(B5,Cash_Book!B:D,2,FALSE)),"Missing","Found") -> Found
A6: 05-04-2026 | B6: TXN1004 | C6: SALARY CREDIT | E6: 8715 | F6: 64671 | H6: =IF(ISNA(VLOOKUP(B6,Cash_Book!B:D,2,FALSE)),"Missing","Found") -> Found
A7: 06-04-2026 | B7: TXN1005 | C7: UPI RECEIPT | E7: 7433 | F7: 72104 | H7: =IF(ISNA(VLOOKUP(B7,Cash_Book!B:D,2,FALSE)),"Missing","Found") -> Found
A8: 07-04-2026 | B8: TXN1006 | C8: ATM WITHDRAWAL | D8: 4347 | F8: 67757 | H8: =IF(ISNA(VLOOKUP(B8,Cash_Book!B:D,2,FALSE)),"Missing","Found") -> Found
A9: 08-04-2026 | B9: TXN1007 | C9: BANK FEES | D9: 4463 | F9: 63294 | H9: =IF(ISNA(VLOOKUP(B9,Cash_Book!B:D,2,FALSE)),"Missing","Found") -> Found
A10: 09-04-2026 | B10: TXN1008 | C10: NEFT CREDIT | E10: 7717 | F10: 71011 | H10: =IF(ISNA(VLOOKUP(B10,Cash_Book!B:D,2,FALSE)),"Missing","Found") -> Found
A11: 10-04-2026 | B11: TXN1009 | C11: NEFT CREDIT | E11: 4562 | F11: 75573 | H11: =IF(ISNA(VLOOKUP(B11,Cash_Book!B:D,2,FALSE)),"Missing","Found") -> Found
A12: 11-04-2026 | B12: TXN1010 | C12: SALARY CREDIT | E12: 3826 | F12: 79399 | H12: =IF(ISNA(VLOOKUP(B12,Cash_Book!B:D,2,FALSE)),"Missing","Found") -> Found
A13: 12-04-2026 | B13: TXN1011 | C13: EFT PAYMENT | D13: 6010 | F13: 73389 | H13: =IF(ISNA(VLOOKUP(B13,Cash_Book!B:D,2,FALSE)),"Missing","Found") -> Found
A14: 13-04-2026 | B14: TXN1012 | C14: NEFT CREDIT | E14: 1679 | F14: 75068 | H14: =IF(ISNA(VLOOKUP(B14,Cash_Book!B:D,2,FALSE)),"Missing","Found") -> Found
A15: 14-04-2026 | B15: TXN1013 | C15: BANK FEES | D15: 738 | F15: 74330 | H15: =IF(ISNA(VLOOKUP(B15,Cash_Book!B:D,2,FALSE)),"Missing","Found") -> Found
A16: 15-04-2026 | B16: TXN1014 | C16: BANK FEES | D16: 726 | F16: 73604 | H16: =IF(ISNA(VLOOKUP(B16,Cash_Book!B:D,2,FALSE)),"Missing","Found") -> Found
A17: 16-04-2026 | B17: TXN1015 | C17: SALARY CREDIT | E17: 4261 | F17: 77865 | H17: =IF(ISNA(VLOOKUP(B17,Cash_Book!B:D,2,FALSE)),"Missing","Found") -> Missing
A18: 17-04-2026 | B18: TXN1016 | C18: ATM WITHDRAWAL | D18: 327 | F18: 77538 | H18: =IF(ISNA(VLOOKUP(B18,Cash_Book!B:D,2,FALSE)),"Missing","Found") -> Found
A19: 18-04-2026 | B19: TXN1017 | C19: SALARY CREDIT | E19: 9248 | F19: 86786 | H19: =IF(ISNA(VLOOKUP(B19,Cash_Book!B:D,2,FALSE)),"Missing","Found") -> Found
A20: 19-04-2026 | B20: TXN1018 | C20: NEFT CREDIT | E20: 1750 | F20: 88536 | H20: =IF(ISNA(VLOOKUP(B20,Cash_Book!B:D,2,FALSE)),"Missing","Found") -> Found
A21: 20-04-2026 | B21: TXN1019 | C21: EFT RECEIPT | E21: 4600 | F21: 93136 | H21: =IF(ISNA(VLOOKUP(B21,Cash_Book!B:D,2,FALSE)),"Missing","Found") -> Found
A22: 21-04-2026 | B22: TXN1020 | C22: CLIENT PAYMENT | E22: 4978 | F22: 98114 | H22: =IF(ISNA(VLOOKUP(B22,Cash_Book!B:D,2,FALSE)),"Missing","Found") -> Found
A23: 22-04-2026 | B23: TXN1021 | C23: EFT PAYMENT | D23: 5630 | F23: 92484 | H23: =IF(ISNA(VLOOKUP(B23,Cash_Book!B:D,2,FALSE)),"Missing","Found") -> Found
A24: 23-04-2026 | B24: TXN1022 | C24: CHEQUE PAYMENT | D24: 3885 | F24: 88599 | H24: =IF(ISNA(VLOOKUP(B24,Cash_Book!B:D,2,FALSE)),"Missing","Found") -> Found
A25: 24-04-2026 | B25: TXN1023 | C25: BANK FEES | D25: 4845 | F25: 83754 | H25: =IF(ISNA(VLOOKUP(B25,Cash_Book!B:D,2,FALSE)),"Missing","Found") -> Found
A26: 25-04-2026 | B26: TXN1024 | C26: NEFT CREDIT | E26: 5343 | F26: 89097 | H26: =IF(ISNA(VLOOKUP(B26,Cash_Book!B:D,2,FALSE)),"Missing","Found") -> Found
A27: 26-04-2026 | B27: TXN1025 | C27: ATM WITHDRAWAL | D27: 5245 | F27: 83852 | H27: =IF(ISNA(VLOOKUP(B27,Cash_Book!B:D,2,FALSE)),"Missing","Found") -> Found
A28: 27-04-2026 | B28: TXN1026 | C28: SALARY CREDIT | E28: 1936 | F28: 85788 | H28: =IF(ISNA(VLOOKUP(B28,Cash_Book!B:D,2,FALSE)),"Missing","Found") -> Found
A29: 28-04-2026 | B29: TXN1027 | C29: SALARY CREDIT | E29: 8843 | F29: 94631 | H29: =IF(ISNA(VLOOKUP(B29,Cash_Book!B:D,2,FALSE)),"Missing","Found") -> Found
A30: 29-04-2026 | B30: TXN1028 | C30: UTILITY BILL | D30: 4804 | F30: 89827 | H30: =IF(ISNA(VLOOKUP(B30,Cash_Book!B:D,2,FALSE)),"Missing","Found") -> Found
A31: 30-04-2026 | B31: TXN1029 | C31: UPI RECEIPT | E31: 570 | F31: 90397 | H31: =IF(ISNA(VLOOKUP(B31,Cash_Book!B:D,2,FALSE)),"Missing","Found") -> Found
A32: 01-04-2026 | B32: TXN1030 | C32: UPI RECEIPT | E32: 7936 | F32: 98333 | H32: =IF(ISNA(VLOOKUP(B32,Cash_Book!B:D,2,FALSE)),"Missing","Found") -> Missing
A33: 02-04-2026 | B33: TXN1031 | C33: ATM WITHDRAWAL | D33: 4087 | F33: 94246 | H33: =IF(ISNA(VLOOKUP(B33,Cash_Book!B:D,2,FALSE)),"Missing","Found") -> Found
A34: 03-04-2026 | B34: TXN1032 | C34: EFT RECEIPT | E34: 5948 | F34: 100194 | H34: =IF(ISNA(VLOOKUP(B34,Cash_Book!B:D,2,FALSE)),"Missing","Found") -> Found
A35: 04-04-2026 | B35: TXN1033 | C35: NEFT CREDIT | E35: 1423 | F35: 101617 | H35: =IF(ISNA(VLOOKUP(B35,Cash_Book!B:D,2,FALSE)),"Missing","Found") -> Found
A36: 05-04-2026 | B36: TXN1034 | C36: SALARY CREDIT | E36: 1766 | F36: 103383 | H36: =IF(ISNA(VLOOKUP(B36,Cash_Book!B:D,2,FALSE)),"Missing","Found") -> Found
A37: 06-04-2026 | B37: TXN1035 | C37: EFT PAYMENT | D37: 7757 | F37: 95626 | H37: =IF(ISNA(VLOOKUP(B37,Cash_Book!B:D,2,FALSE)),"Missing","Found") -> Found
A38: 07-04-2026 | B38: TXN1036 | C38: BANK FEES | D38: 3449 | F38: 92177 | H38: =IF(ISNA(VLOOKUP(B38,Cash_Book!B:D,2,FALSE)),"Missing","Found") -> Found
A39: 08-04-2026 | B39: TXN1037 | C39: CHEQUE PAYMENT | D39: 2936 | F39: 89241 | H39: =IF(ISNA(VLOOKUP(B39,Cash_Book!B:D,2,FALSE)),"Missing","Found") -> Found
A40: 09-04-2026 | B40: TXN1038 | C40: ATM WITHDRAWAL | D40: 7530 | F40: 81711 | H40: =IF(ISNA(VLOOKUP(B40,Cash_Book!B:D,2,FALSE)),"Missing","Found") -> Found
...

Sheet Dashboard
A3: Row Labels | B3: Sum of Debit | C3: Sum of Credit
A4: ATM WITHDRAWAL | B4: 34982
A5: BANK FEES | B5: 40386
A6: CHEQUE PAYMENT | B6: 31886
A7: CLIENT PAYMENT | C7: 45490
A8: EFT PAYMENT | B8: 29824
A9: EFT RECEIPT | C9: 46729
A10: NEFT CREDIT | C10: 61940
A11: SALARY CREDIT | C11: 63612
A12: UPI RECEIPT | C12: 33422
A13: UTILITY BILL | B13: 34415
A14: Grand Total | B14: 171493 | C14: 251193

Sheet Summary
A1: Metric | B1: Formula
A2: Total Transactions | B2: =COUNTA(Cash_Book!B:B)-1 -> 93
A3: Missing Transactions | B3: =COUNTIF(Bank_Statement!H:H,"Missing") -> 8
A4: Mismatched Transactions | B4: =COUNTIF(Cash_Book!G:G,"Mismatch") -> 5
A5: Duplicate Transactions | B5: =COUNTIF(Cash_Book!I:I,">1") -> 2
A6: Total Debit | B6: =SUM(Cash_Book!D:D) -> 171493
A7: Total Credit | B7: =SUM(Cash_Book!E:E) -> 251193

Sheet Cash_Book
A1: Date | B1: Transaction_ID | C1: Description | D1: Debit | E1: Credit | F1: Balance | G1: Amount Check | H1: Bank Balance Lookup | I1: Duplicate Check
A2: 02-04-2026 | B2: TXN1001 | C2: CLIENT PAYMENT | E2: 9769 | F2: 55816 | G2: =IF(OR(D2<>VLOOKUP(B2,Bank_Statement!B:F,3,FALSE),E2<>VLOOKUP(B2,Bank_Statement!B:F,4,FALSE)),"Mismatch","Match") -> Match | H2: =_xlfn.XLOOKUP(B2,Bank_Statement!B2:B101,Bank_Statement!F2:F101,"Not Found") -> 55816 | I2: =COUNTIF(B:B,B2) -> 1
A3: 03-04-2026 | B3: TXN1002 | C3: EFT PAYMENT | D3: 4142 | F3: 51674 | G3: =IF(OR(D3<>VLOOKUP(B3,Bank_Statement!B:F,3,FALSE),E3<>VLOOKUP(B3,Bank_Statement!B:F,4,FALSE)),"Mismatch","Match") -> Match | H3: =_xlfn.XLOOKUP(B3,Bank_Statement!B3:B102,Bank_Statement!F3:F102,"Not Found") -> 51674 | I3: =COUNTIF(B:B,B3) -> 1
A4: 04-04-2026 | B4: TXN1003 | C4: EFT RECEIPT | E4: 4282 | F4: 55956 | G4: =IF(OR(D4<>VLOOKUP(B4,Bank_Statement!B:F,3,FALSE),E4<>VLOOKUP(B4,Bank_Statement!B:F,4,FALSE)),"Mismatch","Match") -> Match | H4: =_xlfn.XLOOKUP(B4,Bank_Statement!B4:B103,Bank_Statement!F4:F103,"Not Found") -> 55956 | I4: =COUNTIF(B:B,B4) -> 1
A5: 05-04-2026 | B5: TXN1004 | C5: SALARY CREDIT | E5: 8715 | F5: 64671 | G5: =IF(OR(D5<>VLOOKUP(B5,Bank_Statement!B:F,3,FALSE),E5<>VLOOKUP(B5,Bank_Statement!B:F,4,FALSE)),"Mismatch","Match") -> Match | H5: =_xlfn.XLOOKUP(B5,Bank_Statement!B5:B104,Bank_Statement!F5:F104,"Not Found") -> 64671 | I5: =COUNTIF(B:B,B5) -> 1
A6: 06-04-2026 | B6: TXN1005 | C6: UPI RECEIPT | E6: 7433 | F6: 72104 | G6: =IF(OR(D6<>VLOOKUP(B6,Bank_Statement!B:F,3,FALSE),E6<>VLOOKUP(B6,Bank_Statement!B:F,4,FALSE)),"Mismatch","Match") -> Match | H6: =_xlfn.XLOOKUP(B6,Bank_Statement!B6:B105,Bank_Statement!F6:F105,"Not Found") -> 72104 | I6: =COUNTIF(B:B,B6) -> 1
A7: 07-04-2026 | B7: TXN1006 | C7: ATM WITHDRAWAL | D7: 4347 | F7: 67757 | G7: =IF(OR(D7<>VLOOKUP(B7,Bank_Statement!B:F,3,FALSE),E7<>VLOOKUP(B7,Bank_Statement!B:F,4,FALSE)),"Mismatch","Match") -> Match | H7: =_xlfn.XLOOKUP(B7,Bank_Statement!B7:B106,Bank_Statement!F7:F106,"Not Found") -> 67757 | I7: =COUNTIF(B:B,B7) -> 1
A8: 08-04-2026 | B8: TXN1007 | C8: BANK FEES | D8: 4463 | F8: 63294 | G8: =IF(OR(D8<>VLOOKUP(B8,Bank_Statement!B:F,3,FALSE),E8<>VLOOKUP(B8,Bank_Statement!B:F,4,FALSE)),"Mismatch","Match") -> Match | H8: =_xlfn.XLOOKUP(B8,Bank_Statement!B8:B107,Bank_Statement!F8:F107,"Not Found") -> 63294 | I8: =COUNTIF(B:B,B8) -> 1
A9: 09-04-2026 | B9: TXN1008 | C9: NEFT CREDIT | E9: 7717 | F9: 71011 | G9: =IF(OR(D9<>VLOOKUP(B9,Bank_Statement!B:F,3,FALSE),E9<>VLOOKUP(B9,Bank_Statement!B:F,4,FALSE)),"Mismatch","Match") -> Match | H9: =_xlfn.XLOOKUP(B9,Bank_Statement!B9:B108,Bank_Statement!F9:F108,"Not Found") -> 71011 | I9: =COUNTIF(B:B,B9) -> 1
A10: 10-04-2026 | B10: TXN1009 | C10: NEFT CREDIT | E10: 4562 | F10: 75573 | G10: =IF(OR(D10<>VLOOKUP(B10,Bank_Statement!B:F,3,FALSE),E10<>VLOOKUP(B10,Bank_Statement!B:F,4,FALSE)),"Mismatch","Match") -> Match | H10: =_xlfn.XLOOKUP(B10,Bank_Statement!B10:B109,Bank_Statement!F10:F109,"Not Found") -> 75573 | I10: =COUNTIF(B:B,B10) -> 1
A11: 11-04-2026 | B11: TXN1010 | C11: SALARY CREDIT | E11: 3826 | F11: 79399 | G11: =IF(OR(D11<>VLOOKUP(B11,Bank_Statement!B:F,3,FALSE),E11<>VLOOKUP(B11,Bank_Statement!B:F,4,FALSE)),"Mismatch","Match") -> Match | H11: =_xlfn.XLOOKUP(B11,Bank_Statement!B11:B110,Bank_Statement!F11:F110,"Not Found") -> 79399 | I11: =COUNTIF(B:B,B11) -> 1
A12: 12-04-2026 | B12: TXN1011 | C12: EFT PAYMENT | D12: 6010 | F12: 73389 | G12: =IF(OR(D12<>VLOOKUP(B12,Bank_Statement!B:F,3,FALSE),E12<>VLOOKUP(B12,Bank_Statement!B:F,4,FALSE)),"Mismatch","Match") -> Match | H12: =_xlfn.XLOOKUP(B12,Bank_Statement!B12:B111,Bank_Statement!F12:F111,"Not Found") -> 73389 | I12: =COUNTIF(B:B,B12) -> 1
A13: 13-04-2026 | B13: TXN1012 | C13: NEFT CREDIT | E13: 1679 | F13: 75068 | G13: =IF(OR(D13<>VLOOKUP(B13,Bank_Statement!B:F,3,FALSE),E13<>VLOOKUP(B13,Bank_Statement!B:F,4,FALSE)),"Mismatch","Match") -> Match | H13: =_xlfn.XLOOKUP(B13,Bank_Statement!B13:B112,Bank_Statement!F13:F112,"Not Found") -> 75068 | I13: =COUNTIF(B:B,B13) -> 1
A14: 14-04-2026 | B14: TXN1013 | C14: BANK FEES | D14: 738 | F14: 74330 | G14: =IF(OR(D14<>VLOOKUP(B14,Bank_Statement!B:F,3,FALSE),E14<>VLOOKUP(B14,Bank_Statement!B:F,4,FALSE)),"Mismatch","Match") -> Match | H14: =_xlfn.XLOOKUP(B14,Bank_Statement!B14:B113,Bank_Statement!F14:F113,"Not Found") -> 74330 | I14: =COUNTIF(B:B,B14) -> 1
A15: 15-04-2026 | B15: TXN1014 | C15: BANK FEES | D15: 726 | F15: 73604 | G15: =IF(OR(D15<>VLOOKUP(B15,Bank_Statement!B:F,3,FALSE),E15<>VLOOKUP(B15,Bank_Statement!B:F,4,FALSE)),"Mismatch","Match") -> Match | H15: =_xlfn.XLOOKUP(B15,Bank_Statement!B15:B114,Bank_Statement!F15:F114,"Not Found") -> 73604 | I15: =COUNTIF(B:B,B15) -> 1
A16: 17-04-2026 | B16: TXN1016 | C16: ATM WITHDRAWAL | D16: 327 | F16: 77538 | G16: =IF(OR(D16<>VLOOKUP(B16,Bank_Statement!B:F,3,FALSE),E16<>VLOOKUP(B16,Bank_Statement!B:F,4,FALSE)),"Mismatch","Match") -> Match | H16: =_xlfn.XLOOKUP(B16,Bank_Statement!B16:B115,Bank_Statement!F16:F115,"Not Found") -> 77538 | I16: =COUNTIF(B:B,B16) -> 1
A17: 18-04-2026 | B17: TXN1017 | C17: SALARY CREDIT | E17: 9248 | F17: 86786 | G17: =IF(OR(D17<>VLOOKUP(B17,Bank_Statement!B:F,3,FALSE),E17<>VLOOKUP(B17,Bank_Statement!B:F,4,FALSE)),"Mismatch","Match") -> Match | H17: =_xlfn.XLOOKUP(B17,Bank_Statement!B17:B116,Bank_Statement!F17:F116,"Not Found") -> 86786 | I17: =COUNTIF(B:B,B17) -> 1
A18: 19-04-2026 | B18: TXN1018 | C18: NEFT CREDIT | E18: 1725 | F18: 88536 | G18: =IF(OR(D18<>VLOOKUP(B18,Bank_Statement!B:F,3,FALSE),E18<>VLOOKUP(B18,Bank_Statement!B:F,4,FALSE)),"Mismatch","Match") -> Mismatch | H18: =_xlfn.XLOOKUP(B18,Bank_Statement!B18:B117,Bank_Statement!F18:F117,"Not Found") -> 88536 | I18: =COUNTIF(B:B,B18) -> 1
A19: 20-04-2026 | B19: TXN1019 | C19: EFT RECEIPT | E19: 4600 | F19: 93136 | G19: =IF(OR(D19<>VLOOKUP(B19,Bank_Statement!B:F,3,FALSE),E19<>VLOOKUP(B19,Bank_Statement!B:F,4,FALSE)),"Mismatch","Match") -> Match | H19: =_xlfn.XLOOKUP(B19,Bank_Statement!B19:B118,Bank_Statement!F19:F118,"Not Found") -> 93136 | I19: =COUNTIF(B:B,B19) -> 1
A20: 21-04-2026 | B20: TXN1020 | C20: CLIENT PAYMENT | E20: 4978 | F20: 98114 | G20: =IF(OR(D20<>VLOOKUP(B20,Bank_Statement!B:F,3,FALSE),E20<>VLOOKUP(B20,Bank_Statement!B:F,4,FALSE)),"Mismatch","Match") -> Match | H20: =_xlfn.XLOOKUP(B20,Bank_Statement!B20:B119,Bank_Statement!F20:F119,"Not Found") -> 98114 | I20: =COUNTIF(B:B,B20) -> 1
A21: 22-04-2026 | B21: TXN1021 | C21: EFT PAYMENT | D21: 5630 | F21: 92484 | G21: =IF(OR(D21<>VLOOKUP(B21,Bank_Statement!B:F,3,FALSE),E21<>VLOOKUP(B21,Bank_Statement!B:F,4,FALSE)),"Mismatch","Match") -> Match | H21: =_xlfn.XLOOKUP(B21,Bank_Statement!B21:B120,Bank_Statement!F21:F120,"Not Found") -> 92484 | I21: =COUNTIF(B:B,B21) -> 1
A22: 23-04-2026 | B22: TXN1022 | C22: CHEQUE PAYMENT | D22: 3885 | F22: 88599 | G22: =IF(OR(D22<>VLOOKUP(B22,Bank_Statement!B:F,3,FALSE),E22<>VLOOKUP(B22,Bank_Statement!B:F,4,FALSE)),"Mismatch","Match") -> Match | H22: =_xlfn.XLOOKUP(B22,Bank_Statement!B22:B121,Bank_Statement!F22:F121,"Not Found") -> 88599 | I22: =COUNTIF(B:B,B22) -> 1
A23: 24-04-2026 | B23: TXN1023 | C23: BANK FEES | D23: 4845 | F23: 83754 | G23: =IF(OR(D23<>VLOOKUP(B23,Bank_Statement!B:F,3,FALSE),E23<>VLOOKUP(B23,Bank_Statement!B:F,4,FALSE)),"Mismatch","Match") -> Match | H23: =_xlfn.XLOOKUP(B23,Bank_Statement!B23:B122,Bank_Statement!F23:F122,"Not Found") -> 83754 | I23: =COUNTIF(B:B,B23) -> 1
A24: 25-04-2026 | B24: TXN1024 | C24: NEFT CREDIT | E24: 5343 | F24: 89097 | G24: =IF(OR(D24<>VLOOKUP(B24,Bank_Statement!B:F,3,FALSE),E24<>VLOOKUP(B24,Bank_Statement!B:F,4,FALSE)),"Mismatch","Match") -> Match | H24: =_xlfn.XLOOKUP(B24,Bank_Statement!B24:B123,Bank_Statement!F24:F123,"Not Found") -> 89097 | I24: =COUNTIF(B:B,B24) -> 1
A25: 26-04-2026 | B25: TXN1025 | C25: ATM WITHDRAWAL | D25: 5245 | F25: 83852 | G25: =IF(OR(D25<>VLOOKUP(B25,Bank_Statement!B:F,3,FALSE),E25<>VLOOKUP(B25,Bank_Statement!B:F,4,FALSE)),"Mismatch","Match") -> Match | H25: =_xlfn.XLOOKUP(B25,Bank_Statement!B25:B124,Bank_Statement!F25:F124,"Not Found") -> 83852 | I25: =COUNTIF(B:B,B25) -> 1
A26: 27-04-2026 | B26: TXN1026 | C26: SALARY CREDIT | E26: 1936 | F26: 85788 | G26: =IF(OR(D26<>VLOOKUP(B26,Bank_Statement!B:F,3,FALSE),E26<>VLOOKUP(B26,Bank_Statement!B:F,4,FALSE)),"Mismatch","Match") -> Match | H26: =_xlfn.XLOOKUP(B26,Bank_Statement!B26:B125,Bank_Statement!F26:F125,"Not Found") -> 85788 | I26: =COUNTIF(B:B,B26) -> 1
A27: 28-04-2026 | B27: TXN1027 | C27: SALARY CREDIT | E27: 8843 | F27: 94631 | G27: =IF(OR(D27<>VLOOKUP(B27,Bank_Statement!B:F,3,FALSE),E27<>VLOOKUP(B27,Bank_Statement!B:F,4,FALSE)),"Mismatch","Match") -> Match | H27: =_xlfn.XLOOKUP(B27,Bank_Statement!B27:B126,Bank_Statement!F27:F126,"Not Found") -> 94631 | I27: =COUNTIF(B:B,B27) -> 1
A28: 29-04-2026 | B28: TXN1028 | C28: UTILITY BILL | D28: 4804 | F28: 89827 | G28: =IF(OR(D28<>VLOOKUP(B28,Bank_Statement!B:F,3,FALSE),E28<>VLOOKUP(B28,Bank_Statement!B:F,4,FALSE)),"Mismatch","Match") -> Match | H28: =_xlfn.XLOOKUP(B28,Bank_Statement!B28:B127,Bank_Statement!F28:F127,"Not Found") -> 89827 | I28: =COUNTIF(B:B,B28) -> 1
A29: 30-04-2026 | B29: TXN1029 | C29: UPI RECEIPT | E29: 570 | F29: 90397 | G29: =IF(OR(D29<>VLOOKUP(B29,Bank_Statement!B:F,3,FALSE),E29<>VLOOKUP(B29,Bank_Statement!B:F,4,FALSE)),"Mismatch","Match") -> Match | H29: =_xlfn.XLOOKUP(B29,Bank_Statement!B29:B128,Bank_Statement!F29:F128,"Not Found") -> 90397 | I29: =COUNTIF(B:B,B29) -> 1
A30: 02-04-2026 | B30: TXN1031 | C30: ATM WITHDRAWAL | D30: 4087 | F30: 94246 | G30: =IF(OR(D30<>VLOOKUP(B30,Bank_Statement!B:F,3,FALSE),E30<>VLOOKUP(B30,Bank_Statement!B:F,4,FALSE)),"Mismatch","Match") -> Match | H30: =_xlfn.XLOOKUP(B30,Bank_Statement!B30:B129,Bank_Statement!F30:F129,"Not Found") -> 94246 | I30: =COUNTIF(B:B,B30) -> 1
A31: 03-04-2026 | B31: TXN1032 | C31: EFT RECEIPT | E31: 5948 | F31: 100194 | G31: =IF(OR(D31<>VLOOKUP(B31,Bank_Statement!B:F,3,FALSE),E31<>VLOOKUP(B31,Bank_Statement!B:F,4,FALSE)),"Mismatch","Match") -> Match | H31: =_xlfn.XLOOKUP(B31,Bank_Statement!B31:B130,Bank_Statement!F31:F130,"Not Found") -> 100194 | I31: =COUNTIF(B:B,B31) -> 1
A32: 04-04-2026 | B32: TXN1033 | C32: NEFT CREDIT | E32: 1423 | F32: 101617 | G32: =IF(OR(D32<>VLOOKUP(B32,Bank_Statement!B:F,3,FALSE),E32<>VLOOKUP(B32,Bank_Statement!B:F,4,FALSE)),"Mismatch","Match") -> Match | H32: =_xlfn.XLOOKUP(B32,Bank_Statement!B32:B131,Bank_Statement!F32:F131,"Not Found") -> 101617 | I32: =COUNTIF(B:B,B32) -> 1
A33: 05-04-2026 | B33: TXN1034 | C33: SALARY CREDIT | E33: 1766 | F33: 103383 | G33: =IF(OR(D33<>VLOOKUP(B33,Bank_Statement!B:F,3,FALSE),E33<>VLOOKUP(B33,Bank_Statement!B:F,4,FALSE)),"Mismatch","Match") -> Match | H33: =_xlfn.XLOOKUP(B33,Bank_Statement!B33:B132,Bank_Statement!F33:F132,"Not Found") -> 103383 | I33: =COUNTIF(B:B,B33) -> 1
A34: 06-04-2026 | B34: TXN1035 | C34: EFT PAYMENT | D34: 7757 | F34: 95626 | G34: =IF(OR(D34<>VLOOKUP(B34,Bank_Statement!B:F,3,FALSE),E34<>VLOOKUP(B34,Bank_Statement!B:F,4,FALSE)),"Mismatch","Match") -> Match | H34: =_xlfn.XLOOKUP(B34,Bank_Statement!B34:B133,Bank_Statement!F34:F133,"Not Found") -> 95626 | I34: =COUNTIF(B:B,B34) -> 1
A35: 07-04-2026 | B35: TXN1036 | C35: BANK FEES | D35: 3449 | F35: 92177 | G35: =IF(OR(D35<>VLOOKUP(B35,Bank_Statement!B:F,3,FALSE),E35<>VLOOKUP(B35,Bank_Statement!B:F,4,FALSE)),"Mismatch","Match") -> Match | H35: =_xlfn.XLOOKUP(B35,Bank_Statement!B35:B134,Bank_Statement!F35:F134,"Not Found") -> 92177 | I35: =COUNTIF(B:B,B35) -> 1
A36: 08-04-2026 | B36: TXN1037 | C36: CHEQUE PAYMENT | D36: 2936 | F36: 89241 | G36: =IF(OR(D36<>VLOOKUP(B36,Bank_Statement!B:F,3,FALSE),E36<>VLOOKUP(B36,Bank_Statement!B:F,4,FALSE)),"Mismatch","Match") -> Match | H36: =_xlfn.XLOOKUP(B36,Bank_Statement!B36:B135,Bank_Statement!F36:F135,"Not Found") -> 89241 | I36: =COUNTIF(B:B,B36) -> 1
A37: 09-04-2026 | B37: TXN1038 | C37: ATM WITHDRAWAL | D37: 7530 | F37: 81711 | G37: =IF(OR(D37<>VLOOKUP(B37,Bank_Statement!B:F,3,FALSE),E37<>VLOOKUP(B37,Bank_Statement!B:F,4,FALSE)),"Mismatch","Match") -> Match | H37: =_xlfn.XLOOKUP(B37,Bank_Statement!B37:B136,Bank_Statement!F37:F136,"Not Found") -> 81711 | I37: =COUNTIF(B:B,B37) -> 1
A38: 10-04-2026 | B38: TXN1039 | C38: SALARY CREDIT | E38: 6404 | F38: 88115 | G38: =IF(OR(D38<>VLOOKUP(B38,Bank_Statement!B:F,3,FALSE),E38<>VLOOKUP(B38,Bank_Statement!B:F,4,FALSE)),"Mismatch","Match") -> Match | H38: =_xlfn.XLOOKUP(B38,Bank_Statement!B38:B137,Bank_Statement!F38:F137,"Not Found") -> 88115 | I38: =COUNTIF(B:B,B38) -> 1
A39: 11-04-2026 | B39: TXN1040 | C39: UTILITY BILL | D39: 4195 | F39: 83970 | G39: =IF(OR(D39<>VLOOKUP(B39,Bank_Statement!B:F,3,FALSE),E39<>VLOOKUP(B39,Bank_Statement!B:F,4,FALSE)),"Mismatch","Match") -> Mismatch | H39: =_xlfn.XLOOKUP(B39,Bank_Statement!B39:B138,Bank_Statement!F39:F138,"Not Found") -> 83970 | I39: =COUNTIF(B:B,B39) -> 1
A40: 12-04-2026 | B40: TXN1041 | C40: CLIENT PAYMENT | E40: 9274 | F40: 93244 | G40: =IF(OR(D40<>VLOOKUP(B40,Bank_Statement!B:F,3,FALSE),E40<>VLOOKUP(B40,Bank_Statement!B:F,4,FALSE)),"Mismatch","Match") -> Match | H40: =_xlfn.XLOOKUP(B40,Bank_Statement!B40:B139,Bank_Statement!F40:F139,"Not Found") -> 93244 | I40: =COUNTIF(B:B,B40) -> 1
...

Sheet Tasks
A1: Tasks
A3: 1. Find missing transactions between Bank Statement and Cash Book.
A4: 2. Use VLOOKUP/XLOOKUP to match Transaction IDs.
A5: 3. Highlight mismatched amounts using Conditional Formatting.
A6: 4. Use IF formula to classify transactions as Match/Mismatch.
A7: 5. Create Pivot Table for Debit and Credit totals.
A8: 6. Find duplicate Transaction IDs using COUNTIF.
A9: 7. Filter only unmatched transactions.
A10: 8. Calculate total Debit and Credit amounts using SUMIF.
A11: 9. Identify timing differences.
A12: 10. Prepare a basic reconciliation summary.
